Workbook

Sheet README
A1: THE UNLOX ACADEMY - DA/DS TRACK
A2: Excel Minor Project - Sales Operations Analytics
A3: Interview-Grade Data Analytics Assessment · 100 Marks
A5: THE SCENARIO
A6: You have just joined the analytics team at a fast-growing multi-category retailer operating across 6 Indian cities.
A7: The head of sales has handed you 5 raw data files - Orders, Customers, Products, Sales Reps, and Targets - and asked
A8: you to answer a set of business questions before the leadership review tomorrow morning.
A10: The data is REAL-WORLD messy: duplicates, missing references, inconsistent case, invalid records, discontinued SKUs.
A11: Part of the assessment is spotting and handling these issues correctly. A wrong-looking answer isn't always wrong -
A12: sometimes the data itself is telling a story.
A14: RULES OF THE ASSESSMENT
A15: 1. Write your answer in the YELLOW cells on each question sheet. Empty answer cell = 0 marks.
... A22: MARKS DISTRIBUTION
A23: Section | B23: Topic | C23: Questions | D23: Marks
A24: Q1 | B24: Lookup Functions (VLOOKUP, INDEX-MATCH, chained lookups) | C24: 8 | D24: 25
A25: Q2 | B25: Data Cleaning & Quality Diagnostics | C25: 6 | D25: 20
A26: Q3 | B26: Conditional Aggregation (SUMIFS, COUNTIFS, IF logic) | C26: 6 | D26: 25
A27: Q4 | B27: Pivot Tables (2D pivots, % of total, calculated fields) | C27: 5 | D27: 20
A28: Q5 | B28: Advanced (Ranking, Running Totals, Multi-condition) | C28: 5 | D28: 10
B29: TOTAL | C29: 30 | D29: 100
A32: PERFORMANCE TIERS
A33: Marks | B33: Tier | C33: Interview Verdict
A34: 85 - 100 | B34: Excellent | C34: Round 1 clear - Excel not a concern
A35: 70 - 84 | B35: Good | C35: Round 1 clear with minor gaps
A36: 55 - 69 | B36: Borderline | C36: Round 1 uncertain - needs revision
A37: 40 - 54 | B37: Weak | C37: Round 1 likely reject - 2 weeks of practice needed
A38: < 40 | B38: Insufficient | C38: Round 1 reject - foundational gaps
A41: DATA SHEETS OVERVIEW
A42: Sheet | B42: Rows | C42: Key Columns | D42: Joins to
A43: Orders | B43: ~2000 | C43: order_id, order_date, customer_id, product_id, sales_rep_id, quantity, unit_price, discount_pct, final_amount, payment_status, ship_city | D43: All others
A44: Customers | B44: 300 | C44: customer_id (PK), customer_name, age, city, segment, signup_date | D44: Orders via customer_id
A45: Products | B45: 60 | C45: product_id (PK), product_name, category, unit_cost, unit_price, is_active | D45: Orders via product_id
A46: Sales_Reps | B46: 30 | C46: rep_id (PK), rep_name, region, hire_date, team_lead_id | D46: Orders via sales_rep_id, self-join via team_lead_id
A47: Targets | B47: 30 × 12 | C47: rep_id (PK), Jan-24 through Dec-24 monthly target values | D47: Sales_Reps via rep_id

Sheet Detail1
A1: Details for Sum of final_amount - Sales Region: South, category: Electronics
A3: order_id | B3: order_date | C3: customer_id | D3: product_id | E3: sales_rep_id | F3: quantity | G3: unit_price | H3: discount_pct | I3: final_amount | J3: payment_status | K3: ship_city | L3: category | M3: segment | N3: age | O3: Sales Region
A4: ORD-01997 | B4: 45585 | C4: CUST-0135 | D4: PROD-006 | E4: R017 | F4: 6 | G4: 3970 | H4: 5.8 | I4: 22438.44 | J4: Pending | K4: Pune | L4: Electronics | M4: SMB | N4: 24 | O4: South
A5: ORD-01963 | B5: 45317 | C5: CUST-0074 | D5: PROD-008 | E5: R007 | F5: 3 | G5: 2660 | H5: 15 | I5: 6783 | J5: Completed | K5: Bengaluru | L5: Electronics | M5: Retail | N5: 27 | O5: South
A6: ORD-01951 | B6: 45538 | C6: CUST-0004 | D6: PROD-007 | E6: R030 | F6: 2 | G6: 1430 | H6: 5 | I6: 2717 | J6: Cancelled | K6: Delhi | L6: Electronics | M6: Retail | N6: 30 | O6: South
A7: ORD-01891 | B7: 45603 | C7: CUST-0168 | D7: PROD-005 | E7: R005 | F7: 10 | G7: 300 | H7: 23.9 | I7: 2283 | J7: Completed | K7: Pune | L7: Electronics | M7: Retail | N7: 25 | O7: South
A8: ORD-01853 | B8: 45650 | C8: CUST-0277 | D8: PROD-009 | E8: R017 | F8: 5 | G8: 1220 | H8: 18.7 | I8: 4959.3 | J8: Completed | K8: Chennai | L8: Electronics | M8: Corporate | N8: 34 | O8: South
A9: ORD-01839 | B9: 45453 | C9: CUST-0170 | D9: PROD-005 | E9: R018 | F9: 6 | G9: 300 | H9: 13.3 | I9: 1560.6 | J9: Completed | K9: Mumbai | L9: Electronics | M9: SMB | N9: 22 | O9: South
A10: ORD-01801 | B10: 45457 | C10: CUST-0118 | D10: PROD-009 | E10: R019 | F10: 7 | G10: 1220 | H10: 13.1 | I10: 7421.26 | J10: Completed | K10: Hyderabad | L10: Electronics | M10: Retail | N10: 26 | O10: South
A11: ORD-01722 | B11: 45376 | C11: CUST-0275 | D11: PROD-008 | E11: R019 | F11: 10 | G11: 2660 | H11: 29.3 | I11: 18806.2 | J11: Completed | K11: Mumbai | L11: Electronics | M11: Retail | N11: 36 | O11: South
A12: ORD-01656 | B12: 45654 | C12: CUST-0240 | D12: PROD-004 | E12: R012 | F12: 7 | G12: 3870 | H12: 5.9 | I12: 25491.69 | J12: Completed | K12: Chennai | L12: Electronics | M12: Corporate | N12: 35 | O12: South
A13: ORD-01601 | B13: 45465 | C13: CUST-0155 | D13: PROD-010 | E13: R022 | F13: 1 | G13: 2640 | H13: 5.9 | I13: 2484.24 | J13: Completed | K13: Pune | L13: Electronics | M13: Corporate | N13: 40 | O13: South
A14: ORD-01532 | B14: 45472 | C14: CUST-0078 | D14: PROD-004 | E14: R025 | F14: 3 | G14: 3870 | H14: 1.9 | I14: 11389.41 | J14: Completed | K14: Delhi | L14: Electronics | M14: Retail | N14: 31 | O14: South
A15: ORD-01507 | B15: 45483 | C15: CUST-0196 | D15: PROD-003 | E15: R009 | F15: 9 | G15: 3570 | H15: 12 | I15: 28274.4 | J15: Completed | K15: Chennai | L15: Electronics | M15: Retail | N15: 26 | O15: South
... A53: ORD-01445 | B53: 45360 | C53: CUST-0291 | D53: PROD-001 | E53: R022 | F53: 4 | G53: 5330 | H53: 22.6 | I53: 16501.68 | J53: Pending | K53: Pune | L53: Electronics | M53: SMB | N53: 29 | O53: South

Sheet Detail2
A1: Details for Sum of final_amount - Sales Region: South, category: Electronics
A3: order_id | B3: order_date | C3: customer_id | D3: product_id | E3: sales_rep_id | F3: quantity | G3: unit_price | H3: discount_pct | I3: final_amount | J3: payment_status | K3: ship_city | L3: category | M3: segment | N3: age | O3: Sales Region
A4: ORD-01997 | B4: 45585 | C4: CUST-0135 | D4: PROD-006 | E4: R017 | F4: 6 | G4: 3970 | H4: 5.8 | I4: 22438.44 | J4: Pending | K4: Pune | L4: Electronics | M4: SMB | N4: 24 | O4: South
A5: ORD-01963 | B5: 45317 | C5: CUST-0074 | D5: PROD-008 | E5: R007 | F5: 3 | G5: 2660 | H5: 15 | I5: 6783 | J5: Completed | K5: Bengaluru | L5: Electronics | M5: Retail | N5: 27 | O5: South
A6: ORD-01951 | B6: 45538 | C6: CUST-0004 | D6: PROD-007 | E6: R030 | F6: 2 | G6: 1430 | H6: 5 | I6: 2717 | J6: Cancelled | K6: Delhi | L6: Electronics | M6: Retail | N6: 30 | O6: South
A7: ORD-01891 | B7: 45603 | C7: CUST-0168 | D7: PROD-005 | E7: R005 | F7: 10 | G7: 300 | H7: 23.9 | I7: 2283 | J7: Completed | K7: Pune | L7: Electronics | M7: Retail | N7: 25 | O7: South
A8: ORD-01853 | B8: 45650 | C8: CUST-0277 | D8: PROD-009 | E8: R017 | F8: 5 | G8: 1220 | H8: 18.7 | I8: 4959.3 | J8: Completed | K8: Chennai | L8: Electronics | M8: Corporate | N8: 34 | O8: South
A9: ORD-01839 | B9: 45453 | C9: CUST-0170 | D9: PROD-005 | E9: R018 | F9: 6 | G9: 300 | H9: 13.3 | I9: 1560.6 | J9: Completed | K9: Mumbai | L9: Electronics | M9: SMB | N9: 22 | O9: South
A10: ORD-01801 | B10: 45457 | C10: CUST-0118 | D10: PROD-009 | E10: R019 | F10: 7 | G10: 1220 | H10: 13.1 | I10: 7421.26 | J10: Completed | K10: Hyderabad | L10: Electronics | M10: Retail | N10: 26 | O10: South
A11: ORD-01722 | B11: 45376 | C11: CUST-0275 | D11: PROD-008 | E11: R019 | F11: 10 | G11: 2660 | H11: 29.3 | I11: 18806.2 | J11: Completed | K11: Mumbai | L11: Electronics | M11: Retail | N11: 36 | O11: South
A12: ORD-01656 | B12: 45654 | C12: CUST-0240 | D12: PROD-004 | E12: R012 | F12: 7 | G12: 3870 | H12: 5.9 | I12: 25491.69 | J12: Completed | K12: Chennai | L12: Electronics | M12: Corporate | N12: 35 | O12: South
A13: ORD-01601 | B13: 45465 | C13: CUST-0155 | D13: PROD-010 | E13: R022 | F13: 1 | G13: 2640 | H13: 5.9 | I13: 2484.24 | J13: Completed | K13: Pune | L13: Electronics | M13: Corporate | N13: 40 | O13: South
A14: ORD-01532 | B14: 45472 | C14: CUST-0078 | D14: PROD-004 | E14: R025 | F14: 3 | G14: 3870 | H14: 1.9 | I14: 11389.41 | J14: Completed | K14: Delhi | L14: Electronics | M14: Retail | N14: 31 | O14: South
A15: ORD-01507 | B15: 45483 | C15: CUST-0196 | D15: PROD-003 | E15: R009 | F15: 9 | G15: 3570 | H15: 12 | I15: 28274.4 | J15: Completed | K15: Chennai | L15: Electronics | M15: Retail | N15: 26 | O15: South
... A53: ORD-01445 | B53: 45360 | C53: CUST-0291 | D53: PROD-001 | E53: R022 | F53: 4 | G53: 5330 | H53: 22.6 | I53: 16501.68 | J53: Pending | K53: Pune | L53: Electronics | M53: SMB | N53: 29 | O53: South

Sheet Visualization

Sheet Orders
A1: order_id | B1: order_date | C1: customer_id | D1: product_id | E1: sales_rep_id | F1: quantity | G1: unit_price | H1: discount_pct | I1: final_amount | J1: payment_status | K1: ship_city | L1: category | N1: segment | O1: age | P1: Sales Region | Q1: Order Month | R1: unit_cost | S1: profit_margin
A2: ORD-00001 | B2: 45549 | C2: CUST-0243 | D2: PROD-014 | E2: R007 | F2: 8 | G2: 3620 | H2: 15.4 | I2: 24500.16 | J2: Completed | K2: Pune | L2: =VLOOKUP(D2,Products!$A:$C,3,FALSE) -> Apparel | N2: =VLOOKUP(C2,Customers!$A:$E,5,FALSE) -> SMB | O2: =VLOOKUP(C2,Customers!$A:$C,3,FALSE) -> 44 | T2: 10.8
A3: ORD-00002 | B3: 45340 | C3: CUST-0202 | D3: PROD-020 | E3: R005 | F3: 2 | G3: 820 | H3: 10.8 | I3: 1462.88 | J3: Pending | K3: Chennai | L3: =VLOOKUP(D3,Products!$A:$C,3,FALSE) -> Apparel | N3: =VLOOKUP(C3,Customers!$A:$E,5,FALSE) -> Retail | O3: =VLOOKUP(C3,Customers!$A:$C,3,FALSE) -> 39 | P3: =VLOOKUP(E2,Sales_Reps!$A:$C,3,FALSE) -> North | Q3: =TEXT(B2,"MMM-YY") -> Sep-24 | R3: =VLOOKUP(D3, Products!A:D, 4, FALSE) -> 391 | S3: =(G3-R3)/G3 -> 0.52317073 | T3: 10.8
A4: ORD-00003 | B4: 45371 | C4: CUST-0098 | D4: PROD-053 | E4: R014 | F4: 8 | G4: 470 | H4: 3.3 | I4: 3635.92 | J4: Pending | K4: Delhi | L4: =VLOOKUP(D4,Products!$A:$C,3,FALSE) -> Sports | N4: =VLOOKUP(C4,Customers!$A:$E,5,FALSE) -> Retail | O4: =VLOOKUP(C4,Customers!$A:$C,3,FALSE) -> 52 | T4: 26
A5: ORD-00004 | B5: 45413 | C5: CUST-0071 | D5: PROD-028 | E5: R006 | F5: 1 | G5: 3660 | H5: 15.7 | I5: 3085.38 | J5: Completed | K5: Delhi | L5: =VLOOKUP(D5,Products!$A:$C,3,FALSE) -> Grocery | N5: =VLOOKUP(C5,Customers!$A:$E,5,FALSE) -> Corporate | O5: =VLOOKUP(C5,Customers!$A:$C,3,FALSE) -> 46 | T5: 29
A6: ORD-00005 | B6: 45611 | C6: CUST-0180 | D6: PROD-012 | E6: R008 | F6: 1 | G6: 3160 | H6: 26 | I6: 2338.4 | J6: Completed | K6: Chennai | L6: =VLOOKUP(D6,Products!$A:$C,3,FALSE) -> Apparel | N6: =VLOOKUP(C6,Customers!$A:$E,5,FALSE) -> Retail | O6: =VLOOKUP(C6,Customers!$A:$C,3,FALSE) -> 36 | P6: =VLOOKUP(E5,Sales_Reps!$A:$C,3,FALSE) -> North | Q6: =TEXT(B5,"MMM-YY") -> May-24 | R6: =VLOOKUP(D6, Products!A:D, 4, FALSE) -> 1886 | S6: =(G6-R6)/G6 -> 0.40316456 | T6: 5.8
A7: ORD-00006 | B7: 45406 | C7: CUST-0275 | D7: PROD-032 | E7: R025 | F7: 4 | G7: 370 | H7: 29 | I7: 1050.8 | J7: Completed | K7: Mumbai | L7: =VLOOKUP(D7,Products!$A:$C,3,FALSE) -> Home | N7: =VLOOKUP(C7,Customers!$A:$E,5,FALSE) -> Retail | O7: =VLOOKUP(C7,Customers!$A:$C,3,FALSE) -> 36 | P7: =VLOOKUP(E6,Sales_Reps!$A:$C,3,FALSE) -> North | Q7: =TEXT(B6,"MMM-YY") -> Nov-24 | R7: =VLOOKUP(D7, Products!A:D, 4, FALSE) -> 288 | S7: =(G7-R7)/G7 -> 0.22162162 | T7: 4.3
A8: ORD-00007 | B8: 45455 | C8: CUST-0293 | D8: PROD-057 | E8: R024 | F8: 3 | G8: 960 | H8: 5.8 | I8: 2712.96 | J8: Completed | K8: Bengaluru | L8: =VLOOKUP(D8,Products!$A:$C,3,FALSE) -> Sports | N8: =VLOOKUP(C8,Customers!$A:$E,5,FALSE) -> Retail | O8: =VLOOKUP(C8,Customers!$A:$C,3,FALSE) -> 27 | P8: =VLOOKUP(E7,Sales_Reps!$A:$C,3,FALSE) -> West | Q8: =TEXT(B7,"MMM-YY") -> Apr-24 | R8: =VLOOKUP(D8, Products!A:D, 4, FALSE) -> 705 | S8: =(G8-R8)/G8 -> 0.265625 | T8: 14.1
A9: ORD-00008 | B9: 45617 | C9: CUST-0281 | D9: PROD-007 | E9: R019 | F9: 8 | G9: 1430 | H9: 2.4 | I9: 11165.44 | J9: Completed | K9: Bengaluru | L9: =VLOOKUP(D9,Products!$A:$C,3,FALSE) -> Electronics | N9: =VLOOKUP(C9,Customers!$A:$E,5,FALSE) -> Corporate | O9: =VLOOKUP(C9,Customers!$A:$C,3,FALSE) -> 57 | T9: 20.7
A10: ORD-00009 | B10: 45549 | C10: CUST-0260 | D10: PROD-038 | E10: R008 | F10: 3 | G10: 5490 | H10: 14.2 | I10: 14131.26 | J10: Completed | K10: Bengaluru | L10: =VLOOKUP(D10,Products!$A:$C,3,FALSE) -> Home | N10: =VLOOKUP(C10,Customers!$A:$E,5,FALSE) -> Retail | O10: =VLOOKUP(C10,Customers!$A:$C,3,FALSE) -> 42 | T10: 18.5
A11: ORD-00010 | B11: 45396 | C11: CUST-0147 | D11: PROD-030 | E11: R028 | F11: 3 | G11: 970 | H11: 1.2 | I11: 2875.08 | J11: Completed | K11: Pune | L11: =VLOOKUP(D11,Products!$A:$C,3,FALSE) -> Grocery | N11: =VLOOKUP(C11,Customers!$A:$E,5,FALSE) -> Retail | O11: =VLOOKUP(C11,Customers!$A:$C,3,FALSE) -> 56 | T11: 28.7
A12: ORD-00011 | B12: 45560 | C12: CUST-0204 | D12: PROD-024 | E12: R010 | F12: 7 | G12: 2270 | H12: 7.1 | I12: 14761.81 | J12: Pending | K12: Hyderabad | L12: =VLOOKUP(D12,Products!$A:$C,3,FALSE) -> Grocery | N12: =VLOOKUP(C12,Customers!$A:$E,5,FALSE) -> Retail | O12: =VLOOKUP(C12,Customers!$A:$C,3,FALSE) -> 60 | T12: 24.6
A13: ORD-00012 | B13: 45332 | C13: CUST-0147 | D13: PROD-010 | E13: R024 | F13: 9 | G13: 2640 | H13: 21.7 | I13: 18604.08 | J13: Completed | K13: Pune | L13: =VLOOKUP(D13,Products!$A:$C,3,FALSE) -> Electronics | N13: =VLOOKUP(C13,Customers!$A:$E,5,FALSE) -> Retail | O13: =VLOOKUP(C13,Customers!$A:$C,3,FALSE) -> 56 | T13: 9.4
A14: ORD-00013 | B14: 45507 | C14: CUST-0280 | D14: PROD-002 | E14: R004 | F14: 3 | G14: 2600 | H14: 4.3 | I14: 7464.6 | J14: Cancelled | K14: Delhi | L14: =VLOOKUP(D14,Products!$A:$C,3,FALSE) -> Electronics | N14: =VLOOKUP(C14,Customers!$A:$E,5,FALSE) -> SMB | O14: =VLOOKUP(C14,Customers!$A:$C,3,FALSE) -> 27 | P14: =VLOOKUP(E13,Sales_Reps!$A:$C,3,FALSE) -> West | Q14: =TEXT(B13,"MMM-YY") -> Feb-24 | R14: =VLOOKUP(D14, Products!A:D, 4, FALSE) -> 1052 | S14: =(G14-R14)/G14 -> 0.59538462 | T14: 16.5
A15: ORD-00014 | B15: 45466 | C15: CUST-0008 | D15: PROD-036 | E15: R025 | F15: 3 | G15: 3250 | H15: 14.1 | I15: 8375.25 | J15: Refunded | K15: Pune | L15: =VLOOKUP(D15,Products!$A:$C,3,FALSE) -> Home | N15: =VLOOKUP(C15,Customers!$A:$E,5,FALSE) -> SMB | O15: =VLOOKUP(C15,Customers!$A:$C,3,FALSE) -> 39 | P15: =VLOOKUP(E14,Sales_Reps!$A:$C,3,FALSE) -> North | Q15: =TEXT(B14,"MMM-YY") -> Aug-24 | R15: =VLOOKUP(D15, Products!A:D, 4, FALSE) -> 1556 | S15: =(G15-R15)/G15 -> 0.52123077 | T15: 18.3
A16: ORD-00015 | B16: 45365 | C16: CUST-0052 | D16: PROD-060 | E16: R003 | F16: 1 | G16: 190 | H16: 20.7 | I16: 150.67 | J16: Completed | K16: Pune | L16: =VLOOKUP(D16,Products!$A:$C,3,FALSE) -> Sports | N16: =VLOOKUP(C16,Customers!$A:$E,5,FALSE) -> Retail | O16: =VLOOKUP(C16,Customers!$A:$C,3,FALSE) -> 38 | P16: =VLOOKUP(E15,Sales_Reps!$A:$C,3,FALSE) -> West | Q16: =TEXT(B15,"MMM-YY") -> Jun-24 | R16: =VLOOKUP(D16, Products!A:D, 4, FALSE) -> 147 | S16: =(G16-R16)/G16 -> 0.22631579 | T16: 10.7
A17: ORD-00016 | B17: 45546 | C17: CUST-0184 | D17: PROD-058 | E17: R014 | F17: 7 | G17: 2400 | H17: 10.2 | I17: 15086.4 | J17: Pending | K17: Pune | L17: =VLOOKUP(D17,Products!$A:$C,3,FALSE) -> Sports | N17: =VLOOKUP(C17,Customers!$A:$E,5,FALSE) -> Retail | O17: =VLOOKUP(C17,Customers!$A:$C,3,FALSE) -> 63 | T17: 26.4
A18: ORD-00017 | B18: 45512 | C18: CUST-0056 | D18: PROD-028 | E18: R023 | F18: 4 | G18: 3660 | H18: 2.6 | I18: 14259.36 | J18: Completed | K18: Bengaluru | L18: =VLOOKUP(D18,Products!$A:$C,3,FALSE) -> Grocery | N18: =VLOOKUP(C18,Customers!$A:$E,5,FALSE) -> SMB | O18: =VLOOKUP(C18,Customers!$A:$C,3,FALSE) -> 46 | T18: 21.1
A19: ORD-00018 | B19: 45654 | C19: CUST-0273 | D19: PROD-047 | E19: R021 | F19: 8 | G19: 3450 | H19: 18.5 | I19: 22494 | J19: Completed | K19: Hyderabad | L19: =VLOOKUP(D19,Products!$A:$C,3,FALSE) -> Beauty | N19: =VLOOKUP(C19,Customers!$A:$E,5,FALSE) -> Corporate | O19: =VLOOKUP(C19,Customers!$A:$C,3,FALSE) -> 32 | P19: =VLOOKUP(E18,Sales_Reps!$A:$C,3,FALSE) -> East | Q19: =TEXT(B18,"MMM-YY") -> Aug-24 | R19: =VLOOKUP(D19, Products!A:D, 4, FALSE) -> 2420 | S19: =(G19-R19)/G19 -> 0.29855072 | T19: 25.8
A20: ORD-00019 | B20: 45626 | C20: CUST-0182 | D20: PROD-051 | E20: R023 | F20: 5 | G20: 3450 | H20: 7.3 | I20: 15990.75 | J20: Completed | K20: Mumbai | L20: =VLOOKUP(D20,Products!$A:$C,3,FALSE) -> Sports | N20: =VLOOKUP(C20,Customers!$A:$E,5,FALSE) -> Retail | O20: =VLOOKUP(C20,Customers!$A:$C,3,FALSE) -> 54 | T20: 8.7
A21: ORD-00020 | B21: 45394 | C21: CUST-0265 | D21: PROD-040 | E21: R023 | F21: 8 | G21: 1080 | H21: 2.2 | I21: 8449.92 | J21: Completed | K21: Chennai | L21: =VLOOKUP(D21,Products!$A:$C,3,FALSE) -> Home | N21: =VLOOKUP(C21,Customers!$A:$E,5,FALSE) -> Retail | O21: =VLOOKUP(C21,Customers!$A:$C,3,FALSE) -> 49 | T21: 0.3
A22: ORD-00021 | B22: 45470 | C22: CUST-0159 | D22: PROD-019 | E22: R006 | F22: 7 | G22: 2480 | H22: 28.7 | I22: 12377.68 | J22: Completed | K22: Hyderabad | L22: =VLOOKUP(D22,Products!$A:$C,3,FALSE) -> Apparel | N22: =VLOOKUP(C22,Customers!$A:$E,5,FALSE) -> Retail | O22: =VLOOKUP(C22,Customers!$A:$C,3,FALSE) -> 32 | P22: =VLOOKUP(E21,Sales_Reps!$A:$C,3,FALSE) -> East | Q22: =TEXT(B21,"MMM-YY") -> Apr-24 | R22: =VLOOKUP(D22, Products!A:D, 4, FALSE) -> 1173 | S22: =(G22-R22)/G22 -> 0.52701613 | T22: 23.9
A23: ORD-00022 | B23: 45354 | C23: CUST-0259 | D23: PROD-036 | E23: R030 | F23: 4 | G23: 3250 | H23: 24.6 | I23: 9802 | J23: Completed | K23: Mumbai | L23: =VLOOKUP(D23,Products!$A:$C,3,FALSE) -> Home | N23: =VLOOKUP(C23,Customers!$A:$E,5,FALSE) -> Retail | O23: =VLOOKUP(C23,Customers!$A:$C,3,FALSE) -> 34 | P23: =VLOOKUP(E22,Sales_Reps!$A:$C,3,FALSE) -> North | Q23: =TEXT(B22,"MMM-YY") -> Jun-24 | R23: =VLOOKUP(D23, Products!A:D, 4, FALSE) -> 1556 | S23: =(G23-R23)/G23 -> 0.52123077 | T23: 18.5
A24: ORD-00023 | B24: 45530 | C24: CUST-0107 | D24: PROD-015 | E24: R030 | F24: 9 | G24: 2720 | H24: 26.2 | I24: 18066.24 | J24: Completed | K24: Pune | L24: =VLOOKUP(D24,Products!$A:$C,3,FALSE) -> Apparel | N24: =VLOOKUP(C24,Customers!$A:$E,5,FALSE) -> Retail | O24: =VLOOKUP(C24,Customers!$A:$C,3,FALSE) -> 50 | T24: 25.5
A25: ORD-00024 | B25: 45472 | C25: CUST-0101 | D25: PROD-044 | E25: R003 | F25: 2 | G25: 1650 | H25: 9.4 | I25: 2989.8 | J25: Completed | K25: Hyderabad | L25: =VLOOKUP(D25,Products!$A:$C,3,FALSE) -> Beauty | N25: =VLOOKUP(C25,Customers!$A:$E,5,FALSE) -> SMB | O25: =VLOOKUP(C25,Customers!$A:$C,3,FALSE) -> 40 | P25: =VLOOKUP(E24,Sales_Reps!$A:$C,3,FALSE) -> West | Q25: =TEXT(B24,"MMM-YY") -> Aug-24 | R25: =VLOOKUP(D25, Products!A:D, 4, FALSE) -> 1222 | S25: =(G25-R25)/G25 -> 0.25939394 | T25: 9.9
A26: ORD-00025 | B26: 45394 | C26: CUST-0142 | D26: PROD-043 | E26: R023 | F26: 6 | G26: 3350 | H26: 6.1 | I26: 18873.9 | J26: Pending | K26: Chennai | L26: =VLOOKUP(D26,Products!$A:$C,3,FALSE) -> Beauty | N26: =VLOOKUP(C26,Customers!$A:$E,5,FALSE) -> Corporate | O26: =VLOOKUP(C26,Customers!$A:$C,3,FALSE) -> 55 | T26: 26.9
A27: ORD-00026 | B27: 45570 | C27: CUST-0250 | D27: PROD-054 | E27: R019 | F27: 2 | G27: 1010 | H27: 16.5 | I27: 1686.7 | J27: Cancelled | K27: Delhi | L27: =VLOOKUP(D27,Products!$A:$C,3,FALSE) -> Sports | N27: =VLOOKUP(C27,Customers!$A:$E,5,FALSE) -> Retail | O27: =VLOOKUP(C27,Customers!$A:$C,3,FALSE) -> 31 | P27: =VLOOKUP(E26,Sales_Reps!$A:$C,3,FALSE) -> East | Q27: =TEXT(B26,"MMM-YY") -> Apr-24 | R27: =VLOOKUP(D27, Products!A:D, 4, FALSE) -> 516 | S27: =(G27-R27)/G27 -> 0.48910891 | T27: 5.3
A28: ORD-00027 | B28: 45401 | C28: CUST-0098 | D28: PROD-046 | E28: R006 | F28: 5 | G28: 4880 | H28: 23.6 | I28: 18641.6 | J28: Completed | K28: Delhi | L28: =VLOOKUP(D28,Products!$A:$C,3,FALSE) -> Beauty | N28: =VLOOKUP(C28,Customers!$A:$E,5,FALSE) -> Retail | O28: =VLOOKUP(C28,Customers!$A:$C,3,FALSE) -> 52 | T28: 25.3
A29: ORD-00028 | B29: 45517 | C29: CUST-0143 | D29: PROD-003 | E29: R015 | F29: 7 | G29: 3570 | H29: 5.8 | I29: 23540.58 | J29: Cancelled | K29: Chennai | L29: =VLOOKUP(D29,Products!$A:$C,3,FALSE) -> Electronics | N29: =VLOOKUP(C29,Customers!$A:$E,5,FALSE) -> SMB | O29: =VLOOKUP(C29,Customers!$A:$C,3,FALSE) -> 52 | T29: 18.7
A30: ORD-00029 | B30: 45363 | C30: CUST-0086 | D30: PROD-048 | E30: R020 | F30: 9 | G30: 5100 | H30: 16.7 | I30: 38234.7 | J30: Completed | K30: Hyderabad | L30: =VLOOKUP(D30,Products!$A:$C,3,FALSE) -> Beauty | N30: =VLOOKUP(C30,Customers!$A:$E,5,FALSE) -> Corporate | O30: =VLOOKUP(C30,Customers!$A:$C,3,FALSE) -> 56 | T30: 4.8
A31: ORD-00030 | B31: 45367 | C31: CUST-0006 | D31: PROD-055 | E31: R005 | F31: 3 | G31: 2860 | H31: 25.8 | I31: 6366.36 | J31: Completed | K31: Pune | L31: =VLOOKUP(D31,Products!$A:$C,3,FALSE) -> Sports | N31: =VLOOKUP(C31,Customers!$A:$E,5,FALSE) -> SMB | O31: =VLOOKUP(C31,Customers!$A:$C,3,FALSE) -> 44 | T31: 19.1
A32: ORD-00031 | B32: 45569 | C32: CUST-0241 | D32: PROD-030 | E32: R006 | F32: 7 | G32: 970 | H32: 29.8 | I32: 4766.58 | J32: Completed | K32: Pune | L32: =VLOOKUP(D32,Products!$A:$C,3,FALSE) -> Grocery | N32: =VLOOKUP(C32,Customers!$A:$E,5,FALSE) -> Corporate | O32: =VLOOKUP(C32,Customers!$A:$C,3,FALSE) -> 47 | T32: 1
A33: ORD-00032 | B33: 45641 | C33: CUST-0035 | D33: PROD-021 | E33: R026 | F33: 4 | G33: 2760 | H33: 5.9 | I33: 10388.64 | J33: Completed | K33: Hyderabad | L33: =VLOOKUP(D33,Products!$A:$C,3,FALSE) -> Grocery | N33: =VLOOKUP(C33,Customers!$A:$E,5,FALSE) -> Retail | O33: =VLOOKUP(C33,Customers!$A:$C,3,FALSE) -> 53 | T33: 15.8
A34: ORD-00033 | B34: 45343 | C34: CUST-0273 | D34: PROD-037 | E34: R009 | F34: 10 | G34: 660 | H34: 18.3 | I34: 5392.2 | J34: Pending | K34: Hyderabad | L34: =VLOOKUP(D34,Products!$A:$C,3,FALSE) -> Home | N34: =VLOOKUP(C34,Customers!$A:$E,5,FALSE) -> Corporate | O34: =VLOOKUP(C34,Customers!$A:$C,3,FALSE) -> 32 | P34: =VLOOKUP(E33,Sales_Reps!$A:$C,3,FALSE) -> West | Q34: =TEXT(B33,"MMM-YY") -> Dec-24 | R34: =VLOOKUP(D34, Products!A:D, 4, FALSE) -> 329 | S34: =(G34-R34)/G34 -> 0.50151515 | T34: 12.2
A35: ORD-00034 | B35: 45576 | C35: CUST-0064 | D35: PROD-036 | E35: R019 | F35: 1 | G35: 3250 | H35: 10.7 | I35: 2902.25 | J35: Completed | K35: Hyderabad | L35: =VLOOKUP(D35,Products!$A:$C,3,FALSE) -> Home | N35: =VLOOKUP(C35,Customers!$A:$E,5,FALSE) -> SMB | O35: =VLOOKUP(C35,Customers!$A:$C,3,FALSE) -> 40 | P35: =VLOOKUP(E34,Sales_Reps!$A:$C,3,FALSE) -> South | Q35: =TEXT(B34,"MMM-YY") -> Feb-24 | R35: =VLOOKUP(D35, Products!A:D, 4, FALSE) -> 1556 | S35: =(G35-R35)/G35 -> 0.52123077 | T35: 19.9
A36: ORD-00035 | B36: 45462 | C36: CUST-0118 | D36: PROD-048 | E36: R019 | F36: 8 | G36: 5100 | H36: 26.4 | I36: 30028.8 | J36: Cancelled | K36: Hyderabad | L36: =VLOOKUP(D36,Products!$A:$C,3,FALSE) -> Beauty | N36: =VLOOKUP(C36,Customers!$A:$E,5,FALSE) -> Retail | O36: =VLOOKUP(C36,Customers!$A:$C,3,FALSE) -> 26 | P36: =VLOOKUP(E35,Sales_Reps!$A:$C,3,FALSE) -> East | Q36: =TEXT(B35,"MMM-YY") -> Oct-24 | R36: =VLOOKUP(D36, Products!A:D, 4, FALSE) -> 2237 | S36: =(G36-R36)/G36 -> 0.56137255 | T36: 28.8
A37: ORD-00036 | B37: 45442 | C37: CUST-0013 | D37: PROD-040 | E37: R021 | F37: 1 | G37: 1080 | H37: 5.1 | I37: 1024.92 | J37: Completed | K37: Delhi | L37: =VLOOKUP(D37,Products!$A:$C,3,FALSE) -> Home | N37: =VLOOKUP(C37,Customers!$A:$E,5,FALSE) -> Retail | O37: =VLOOKUP(C37,Customers!$A:$C,3,FALSE) -> 41 | T37: 1.1
A38: ORD-00037 | B38: 45646 | C38: CUST-0177 | D38: PROD-038 | E38: R009 | F38: 2 | G38: 5490 | H38: 21.1 | I38: 8663.22 | J38: Cancelled | K38: Mumbai | L38: =VLOOKUP(D38,Products!$A:$C,3,FALSE) -> Home | N38: =VLOOKUP(C38,Customers!$A:$E,5,FALSE) -> SMB | O38: =VLOOKUP(C38,Customers!$A:$C,3,FALSE) -> 36 | P38: =VLOOKUP(E37,Sales_Reps!$A:$C,3,FALSE) -> East | Q38: =TEXT(B37,"MMM-YY") -> May-24 | R38: =VLOOKUP(D38, Products!A:D, 4, FALSE) -> 2549 | S38: =(G38-R38)/G38 -> 0.53570128 | T38: 21
A39: ORD-00038 | B39: 45478 | C39: CUST-0186 | D39: PROD-060 | E39: R001 | F39: 7 | G39: 190 | H39: 28.7 | I39: 948.29 | J39: Completed | K39: Bengaluru | L39: =VLOOKUP(D39,Products!$A:$C,3,FALSE) -> Sports | N39: =VLOOKUP(C39,Customers!$A:$E,5,FALSE) -> Retail | O39: =VLOOKUP(C39,Customers!$A:$C,3,FALSE) -> 42 | T39: 22.2
A40: ORD-00039 | B40: 45355 | C40: CUST-0069 | D40: PROD-058 | E40: R015 | F40: 6 | G40: 2400 | H40: 2.7 | I40: 14011.2 | J40: Completed | K40: Chennai | L40: =VLOOKUP(D40,Products!$A:$C,3,FALSE) -> Sports | N40: =VLOOKUP(C40,Customers!$A:$E,5,FALSE) -> Retail | O40: =VLOOKUP(C40,Customers!$A:$C,3,FALSE) -> 51 | T40: 5.4
...

Sheet Customers
A1: customer_id | B1: customer_name | C1: age | D1: city | E1: segment | F1: signup_date
A2: CUST-0001 | B2: Amit Agarwal | C2: 36 | D2: Pune | E2: Retail | F2: 44819
A3: CUST-0002 | B3: Vihaan Malhotra | C3: 42 | D3: Pune | E3: Corporate | F3: 44984
A4: CUST-0003 | B4: Navya Malhotra | C4: 33 | D4: Mumbai | E4: Retail | F4: 44059
A5: CUST-0004 | B5: Aaradhya Mehta | C5: 53 | D5: delhi | E5: Retail | F5: 44054
A6: CUST-0005 | B6: Myra Malhotra | C6: 52 | D6: Chennai | E6: Corporate | F6: 45037
A7: CUST-0006 | B7: Shaurya Iyer | C7: 44 | D7: Pune | E7: SMB | F7: 44302
A8: CUST-0007 | B8: Dhruv Joshi | C8: 47 | D8: Bengaluru | E8: Retail | F8: 44498
A9: CUST-0008 | B9: Kavita Malhotra | C9: 39 | D9: Pune | E9: SMB | F9: 45162
A10: CUST-0009 | B10: Neha Malhotra | C10: 61 | D10: Mumbai | E10: Retail | F10: 44343
A11: CUST-0010 | B11: Aaradhya Gupta | C11: 61 | D11: Mumbai | E11: SMB | F11: 44975
A12: CUST-0011 | B12: Diya Menon | C12: 41 | D12: Chennai | E12: Corporate | F12: 44821
A13: CUST-0012 | B13: Prisha Desai | C13: 43 | D13: Pune | E13: Retail | F13: 44718
... A301: CUST-0300 | B301: Rohit Nair | C301: 38 | D301: Mumbai | E301: Retail | F301: 43932

Sheet Products
A1: product_id | B1: product_name | C1: category | D1: unit_cost | E1: unit_price | F1: is_active
A2: PROD-001 | B2: Smartphone Pro | C2: Electronics | D2: 2405 | E2: 5330 | F2: TRUE
A3: PROD-002 | B3: Wireless Earbuds | C3: Electronics | D3: 1052 | E3: 2600 | F3: TRUE
A4: PROD-003 | B4: Smart Watch | C4: Electronics | D4: 1665 | E4: 3570 | F4: TRUE
A5: PROD-004 | B5: Laptop Bag | C5: Electronics | D5: 1559 | E5: 3870 | F5: TRUE
A6: PROD-005 | B6: Power Bank | C6: Electronics | D6: 128 | E6: 300 | F6: TRUE
A7: PROD-006 | B7: Bluetooth Speaker | C7: Electronics | D7: 2865 | E7: 3970 | F7: TRUE
A8: PROD-007 | B8: USB-C Cable | C8: Electronics | D8: 861 | E8: 1430 | F8: TRUE
A9: PROD-008 | B9: Wireless Mouse | C9: Electronics | D9: 1259 | E9: 2660 | F9: FALSE
A10: PROD-009 | B10: Mechanical Keyboard | C10: Electronics | D10: 517 | E10: 1220 | F10: TRUE
A11: PROD-010 | B11: Tablet Stand | C11: Electronics | D11: 1149 | E11: 2640 | F11: TRUE
A12: PROD-011 | B12: Cotton T-Shirt | C12: Apparel | D12: 1748 | E12: 3450 | F12: TRUE
A13: PROD-012 | B13: Denim Jeans | C13: Apparel | D13: 1886 | E13: 3160 | F13: TRUE
... A61: PROD-060 | B61: Gym Gloves | C61: Sports | D61: 147 | E61: 190 | F61: TRUE

Sheet Sales_Reps
A1: rep_id | B1: rep_name | C1: region | D1: hire_date | E1: team_lead_id
A2: R001 | B2: Rajesh Malhotra | C2: North | D2: 44207
A3: R002 | B3: Sunita Malhotra | C3: North | D3: 44028
A4: R003 | B4: Amit Singh | C4: North | D4: 43651
A5: R004 | B5: Priya Singh | C5: North | D5: 44907
A6: R005 | B6: Vikram Patel | C6: North | D6: 43588 | E6: R001
A7: R006 | B7: Neha Desai | C7: North | D7: 44131 | E7: R001
A8: R007 | B8: Suresh Menon | C8: North | D8: 43493 | E8: R001
A9: R008 | B9: Kavita Patel | C9: North | D9: 44693 | E9: R001
A10: R009 | B10: Manoj Patel | C10: South | D10: 44804 | E10: R002
A11: R010 | B11: Divya Rao | C11: South | D11: 43904 | E11: R002
A12: R011 | B12: Anil Verma | C12: South | D12: 44622 | E12: R002
A13: R012 | B13: Pooja Nair | C13: South | D13: 44890 | E13: R002
A14: R013 | B14: Sanjay Kapoor | C14: South | D14: 45215 | E14: R002
A15: R014 | B15: Ritu Menon | C15: South | D15: 44469 | E15: R002
A16: R015 | B16: Deepak Shah | C16: South | D16: 45231 | E16: R002
A17: R016 | B17: Anjali Chopra | C17: South | D17: 43614 | E17: R002
... A31: R030 | B31: Kiran Bhatt | C31: West | D31: 44506 | E31: R004

Sheet Targets
A1: rep_id | B1: Jan-24 | C1: Feb-24 | D1: Mar-24 | E1: Apr-24 | F1: May-24 | G1: Jun-24 | H1: Jul-24 | I1: Aug-24 | J1: Sep-24 | K1: Oct-24 | L1: Nov-24 | M1: Dec-24
A2: R001 | B2: 231324 | C2: 171682 | D2: 234376 | E2: 326967 | F2: 350588 | G2: 385324 | H2: 307980 | I2: 327947 | J2: 181016 | K2: 374039 | L2: 212805 | M2: 405999
A3: R002 | B3: 438126 | C3: 346266 | D3: 329993 | E3: 370744 | F3: 294660 | G3: 341556 | H3: 151934 | I3: 223794 | J3: 438641 | K3: 344308 | L3: 296172 | M3: 304288
A4: R003 | B4: 358703 | C4: 320519 | D4: 327321 | E4: 298753 | F4: 254636 | G4: 351929 | H4: 264723 | I4: 216459 | J4: 391945 | K4: 362426 | L4: 289199 | M4: 301863
A5: R004 | B5: 389594 | C5: 376422 | D5: 324156 | E5: 420255 | F5: 409107 | G5: 269954 | H5: 179097 | I5: 370568 | J5: 387395 | K5: 243454 | L5: 232530 | M5: 201999
A6: R005 | B6: 436862 | C6: 391158 | D6: 340224 | E6: 170548 | F6: 229390 | G6: 349525 | H6: 154683 | I6: 320848 | J6: 354452 | K6: 377180 | L6: 342347 | M6: 183362
A7: R006 | B7: 348734 | C7: 358191 | D7: 250385 | E7: 219657 | F7: 249365 | G7: 435704 | H7: 260892 | I7: 250741 | J7: 358402 | K7: 379858 | L7: 213280 | M7: 224634
A8: R007 | B8: 280057 | C8: 330342 | D8: 336856 | E8: 227425 | F8: 233647 | G8: 307088 | H8: 370724 | I8: 440008 | J8: 406347 | K8: 217357 | L8: 299289 | M8: 214568
A9: R008 | B9: 252886 | C9: 206057 | D9: 318209 | E9: 411230 | F9: 448660 | G9: 171135 | H9: 305339 | I9: 432264 | J9: 294273 | K9: 371409 | L9: 284207 | M9: 437068
A10: R009 | B10: 268752 | C10: 393256 | D10: 310649 | E10: 246237 | F10: 271287 | G10: 314545 | H10: 406506 | I10: 334930 | J10: 348625 | K10: 408928 | L10: 243749 | M10: 418409
A11: R010 | B11: 384734 | C11: 156698 | D11: 283679 | E11: 276085 | F11: 409270 | G11: 285230 | H11: 304233 | I11: 178221 | J11: 284216 | K11: 287373 | L11: 229082 | M11: 298969
A12: R011 | B12: 186029 | C12: 151419 | D12: 253251 | E12: 379757 | F12: 204209 | G12: 179396 | H12: 378008 | I12: 182649 | J12: 267772 | K12: 350352 | L12: 358042 | M12: 359960
A13: R012 | B13: 352158 | C13: 251181 | D13: 321255 | E13: 300863 | F13: 241731 | G13: 393275 | H13: 313561 | I13: 283604 | J13: 429065 | K13: 194420 | L13: 254168 | M13: 389283
... A31: R030 | B31: 151584 | C31: 221679 | D31: 385157 | E31: 290386 | F31: 236041 | G31: 407985 | H31: 184446 | I31: 342894 | J31: 180344 | K31: 292917 | L31: 314858 | M31: 364057

Sheet Q1_Lookups
A1: Q1 - LOOKUP FUNCTIONS (25 marks total)
A2: VLOOKUP · INDEX-MATCH · Two-way lookup · Chain lookup · Approximate lookup · Self-join
A4: Q# | B4: Question | C4: Marks | D4: Hint | E4: Your Answer | F4: Format
A5: Q1.1 | B5: For order ORD-00234, what is the customer_id? | C5: 3 | D5: Simple VLOOKUP on Orders sheet. | E5: {=_xlfn.XLOOKUP("ORD-00234",Orders!A:A,Orders!C:C)} -> CUST-0173 | F5: CUST-####
A6: Q1.2 | B6: For order ORD-00456, what is the product_name? (You will need to look up the product_id first, then find its name in Products.) | C6: 3 | D6: Two-step lookup, or nested VLOOKUP. | E6: {=_xlfn.XLOOKUP( _xlfn.XLOOKUP("ORD-00456",Orders!A:A,Orders!D:D), Products!A:A, Products!B:B )} -> Dumbbells 5kg | F6: Text
A7: Q1.3 | B7: For order ORD-00987, what is the rep_name of the sales rep? Note: the rep_name is in a column that appears to the LEFT of what you might look up first. | C7: 3 | D7: VLOOKUP has directional limits - INDEX/MATCH does not. | E7: {=_xlfn.XLOOKUP( _xlfn.XLOOKUP("ORD-00987",Orders!A:A,Orders!E:E), Sales_Reps!A:A, Sales_Reps!B:B )} -> Nisha Menon | F7: Text
A8: Q1.4 | B8: From the Targets sheet, what is the target value for rep R012 in the month Mar-24? | C8: 4 | D8: Two-way lookup: row = rep_id, column = month. | E8: {=_xlfn.XLOOKUP("R012",Targets!A:A,Targets!D:D)} -> 321255 | F8: Whole number
A9: Q1.5 | B9: For order ORD-01500, what is the CATEGORY of the product ordered? (Chain: order → product_id → category) | C9: 4 | D9: Multi-hop lookup across sheets. | E9: {=_xlfn.XLOOKUP(_xlfn.XLOOKUP("ORD-01500",Orders!A:A,Orders!D:D),Products!A:A,Products!C:C)} -> Electronics | F9: Text
A10: Q1.6 | B10: For order ORD-00789, which DISCOUNT SLAB does it fall in? Use the slab table below (rows 20-24). Slab breakpoints are the LOWER bound of each range. | C10: 3 | D10: Approximate-match VLOOKUP (sort ascending, TRUE / omit last arg). | E10: {=VLOOKUP(_xlfn.XLOOKUP("ORD-00789",Orders!A:A,Orders!H:H),$B$18:$C$21,2,TRUE)} -> Bronze | F10: Text
A11: Q1.7 | B11: For order ORD-01234, in one cell produce the string: "<rep_name> (<sales_region>)" - e.g. "Amit Singh (South)". | C11: 3 | D11: Two lookups joined with & or CONCATENATE. | E11: {=_xlfn.XLOOKUP(_xlfn.XLOOKUP("ORD-01234",Orders!A:A,Orders!E:E),Sales_Reps!A:A,Sales_Reps!B:B)&" ("&_xlfn.XLOOKUP(_xlfn.XLOOKUP("ORD-01234",Orders!A:A,Orders!E:E),Sales_Reps!A:A,Sales_Reps!C:C)&")"} -> Sanjay Kapoor (South) | F11: Text
A12: Q1.8 | B12: What is the rep_name of the TEAM LEAD for rep R017? (The Sales_Reps sheet has team_lead_id - you need to self-join to find that person's name.) | C12: 2 | D12: Look up the team_lead_id, then look up THAT id's rep_name. | E12: {=_xlfn.XLOOKUP(_xlfn.XLOOKUP("R017",Sales_Reps!A:A,Sales_Reps!E:E),Sales_Reps!A:A,Sales_Reps!B:B)} -> Amit Singh | F12: Text
B15: DISCOUNT SLAB REFERENCE TABLE (use for Q1.6)
B17: Discount % (Lower) | C17: Slab
B18: 0 | C18: Bronze
B19: 5 | C19: Silver
B20: 15 | C20: Gold
B21: 25 | C21: Platinum

Sheet Q2_Cleaning
A1: Q2 - DATA CLEANING & QUALITY DIAGNOSTICS (20 marks total)
A2: Duplicates · Whitespace · Case Inconsistency · Referential Integrity · Discontinued SKUs · Anomaly Patterns
A4: Q# | B4: Question | C4: Marks | D4: Hint | E4: Your Answer | F4: Format
A5: Q2.1 | B5: How many DUPLICATE rows exist in the Orders sheet (i.e., how many order_id values appear more than once)? Count each duplicate as ONE (not the extras). | C5: 3 | D5: COUNTIF > 1, then count. Watch what you're counting - rows or IDs. | E5: {=SUMPRODUCT((COUNTIF(Orders!A2:A2001,Orders!A2:A2001)>1)/COUNTIF(Orders!A2:A2001,Orders!A2:A2001))} -> 20 | F5: Whole number
A6: Q2.2 | B6: How many customers in the Customers sheet have LEADING or TRAILING whitespace in their customer_name? | C6: 3 | D6: Compare LEN vs LEN(TRIM). Or use SUMPRODUCT with a boolean. | E6: {=SUMPRODUCT(--(Customers!B2:B301<>TRIM(Customers!B2:B301)))} -> 15 | F6: Whole number
A7: Q2.3 | B7: The Customers sheet has some cities in inconsistent case (e.g., "mumbai", "MUMBAI", "Mumbai"). How many DISTINCT cities exist AFTER standardizing case? | C7: 3 | D7: Combine PROPER/UPPER with a de-dup count. SUMPRODUCT + 1/COUNTIF trick works. | E7: {=COUNTA(_xludf.UNIQUE(LOWER(TRIM(Customers!D2:D301))))} -> 1 | F7: Whole number
A8: Q2.4 | B8: How many orders reference a customer_id that DOES NOT EXIST in the Customers sheet? (Broken foreign key) | C8: 4 | D8: Use MATCH with ISNA/ISERROR, then count. | E8: {=SUMPRODUCT(--ISNA(MATCH(Orders!C2:C2001,Customers!A2:A301,0)))} -> 30 | F8: Whole number
A9: Q2.5 | B9: How many orders reference a product that is currently DISCONTINUED (is_active = FALSE in the Products sheet)? | C9: 3 | D9: VLOOKUP the is_active flag, then count where FALSE. | E9: {=SUMPRODUCT(--(_xlfn.XLOOKUP(Orders!D2:D2001,Products!A2:A61,Products!F2:F61)=FALSE))} -> 0 | F9: Whole number
A10: Q2.6 | B10: Find the "suspicious pattern": how many orders have payment_status = "Cancelled" AND a discount_pct > 20%? (This pattern often indicates promo abuse - a real-world diagnostic query.) | C10: 4 | D10: COUNTIFS with two criteria. | E10: =COUNTIFS(Orders!J2:J2001,"Cancelled",Orders!H2:H2001,">20") -> 58 | F10: Whole number

Sheet Q3_Aggregation
A1: Q3 - CONDITIONAL AGGREGATION (25 marks total)
A2: SUMIFS · COUNTIFS · AVERAGEIFS · Nested IF logic · Multi-sheet aggregation · Top-N logic
A4: Q# | B4: Question | C4: Marks | D4: Hint | E4: Your Answer | F4: Format
A5: Q3.1 | B5: What is the TOTAL REVENUE (sum of final_amount) for orders in Q3 2024 (Jul-Sep) where ship_city is Mumbai? | C5: 4 | D5: SUMIFS with 3 conditions: date >= start, date <= end, city = Mumbai. Beware case issues. | E5: =SUMIFS(Orders!I:I,Orders!B:B,">="&DATE(2024,7,1),Orders!B:B,"<="&DATE(2024,9,30),Orders!K:K,"Mumbai") -> 1217239 | F5: Currency
A6: Q3.2 | B6: How many orders have discount_pct > 15% AND payment_status = "Completed"? | C6: 3 | D6: COUNTIFS with two conditions. | E6: =COUNTIFS(Orders!H:H,">15",Orders!J:J,"Completed") -> 723 | F6: Whole number
A7: Q3.3 | B7: What is the AVERAGE final_amount for orders where the product CATEGORY is "Electronics" AND the customer SEGMENT is "Corporate"? Note: Both fields come from OTHER sheets - you'll need helper columns. | C7: 5 | D7: Helper columns in Orders: VLOOKUP category from Products, VLOOKUP segment from Customers. Then AVERAGEIFS. | E7: =AVERAGEIFS(Orders!$I:$I,Orders!$L:$L,"Electronics",Orders!$N:$N,"Corporate") -> 13981.402 | F7: Currency
A8: Q3.4 | B8: What is the COMBINED REVENUE of the TOP 3 reps by total revenue? (Sum of the 3 highest rep totals.) | C8: 4 | D8: Compute per-rep totals, then use SUMPRODUCT with LARGE, or sort and sum top 3. | E8: 3342678.5 | F8: Currency
A9: Q3.5 | B9: For rep R015 in Nov-24: compute the actual revenue and compare to the target (from Targets sheet). Report the PERFORMANCE TIER using: <80% → "Below", 80-120% → "On Track", >120% → "Exceeds". Return only the tier text. | C9: 5 | D9: Nested IF (or IFS): compute actual/target ratio, then classify. | E9: {=IF(SUMIFS(Orders!$I:$I,Orders!$E:$E,"R015",Orders!$B:$B,">="&DATE(2024,11,1),Orders!$B:$B,"<"&DATE(2024,12,1))/INDEX(Targets!$L:$L,MATCH("R015",Targets!$A:$A,0))<0.8,"Below",IF(SUMIFS(Orders!$I:$I,Orders!$E:$E,"R015",Orders!$B:$B,">="&DATE(2024,11,1),Orders!$B:$B,"<"&DATE(2024,12,1))/INDEX(Targets!$L:$L,MATCH("R015",Targets!$A:$A,0))<=1.2,"On Track","Exceeds"))} -> Below | F9: Text
A10: Q3.6 | B10: What is the TOTAL revenue from Corporate segment customers aged between 30 and 40 (both inclusive)? | C10: 4 | D10: Helper columns for age and segment. Then SUMIFS with numeric range. | E10: =SUMIFS(Orders!$I:$I,Orders!$E:$E,"R015",Orders!$B:$B,">="&DATE(2024,11,1),Orders!$B:$B,"<"&DATE(2024,12,1)) -> 97394.65 | F10: Currency

Sheet Practice Sheet
A3: sales_rep_id | B3: Sum of final_amount
A4: R006 | B4: 1138648.7 | D4: =SUM(B4:B6) -> 3342678.5
A5: R018 | B5: 1112289.6
A6: R015 | B6: 1091740.2
A7: R022 | B7: 1069570.5
A8: R029 | B8: 1016696.8
A9: R014 | B9: 995713.54
A10: R003 | B10: 986692.91
A11: R023 | B11: 983787.48
A12: R002 | B12: 980063.66
A13: R019 | B13: 971183.52
A14: R027 | B14: 917092.62
A15: R009 | B15: 914554.72
A16: R020 | B16: 906107.71
... A34: Grand Total | B34: 26572948
A38: {=IF(SUMIFS(Orders!$I:$I,Orders!$E:$E,"R015",Orders!$B:$B,">="&DATE(2024,11,1),Orders!$B:$B,"<"&DATE(2024,12,1))/INDEX(Targets!$L:$L,MATCH("R015",Targets!$A:$A,0))<0.8,"Below",IF(SUMIFS(Orders!$I:$I,Orders!$E:$E,"R015",Orders!$B:$B,">="&DATE(2024,11,1),Orders!$B:$B,"<"&DATE(2024,12,1))/INDEX(Targets!$L:$L,MATCH("R015",Targets!$A:$A,0))<=1.2,"On Track","Exceeds"))} -> Below
A40: =SUMIFS(Orders!$I:$I,Orders!$E:$E,"R015",Orders!$B:$B,">="&DATE(2024,11,1),Orders!$B:$B,"<"&DATE(2024,12,1)) -> 97394.65

Sheet Q4_Pivot
A1: Q4 - PIVOT TABLES (20 marks total)
A2: 2D Pivots · Filters · % of Row Total · Date Grouping · Calculated Fields · Cross-Sheet Data
A4: Q# | B4: Question | C4: Marks | D4: Hint | E4: Your Answer | F4: Format
A5: Q4.1 | B5: Build a pivot with sales_region as rows and product category as columns, values = SUM of final_amount. What value appears at the intersection of "South" and "Electronics"? | C5: 4 | D5: You need to add category (from Products) and region (from Sales_Reps) as columns to Orders first. Insert PivotTable from combined data. | E5: 635816.35 | F5: Currency
A6: Q4.2 | B6: Build a pivot: rows = order month (Jan-24 through Dec-24), columns = sales_rep_id, values = SUM of final_amount. What is the HIGHEST single value in the entire pivot? (One number.) | C6: 4 | D6: After building, use MAX() over the pivot data range, or scan visually. | E6: 15508548 | F6: Currency
A7: Q4.3 | B7: For the North sales_region only: what PERCENTAGE of total revenue comes from the Apparel category? Configure the pivot with Show Values As → % of Row Total. | C7: 4 | D7: Pivot: rows=region, cols=category, values=sum(final_amount), Show Values As = % of Row Total. | E7: 0.1382 | F7: Percentage
A8: Q4.4 | B8: Group order dates by QUARTER in a pivot. What is the total revenue for Q4 2024 (Oct-Dec)? | C8: 4 | D8: PivotTable → Group By → Quarter. Or SUMIFS with date range. | E8: 26516373 | F8: Currency
A9: Q4.5 | B9: Create a CALCULATED FIELD in the pivot: profit_margin = (unit_price - unit_cost) / unit_price. What is the AVERAGE profit_margin for orders shipped to Delhi? Give as a percentage. | C9: 4 | D9: Add unit_cost via VLOOKUP as helper column. Create pivot calculated field, filter to Delhi. | E9: 0.455 | F9: Percentage

Sheet Practice sheet 2
A3: Sum of final_amount | B3: category
A4: Sales Region | B4: Apparel | C4: Beauty | D4: Electronics | E4: Grocery | F4: Home | G4: Sports | H4: Grand Total
A5: East | B5: 229296.13 | C5: 781125.36 | D5: 464217.62 | E5: 611143.6 | F5: 355997.28 | G5: 393778.21 | H5: 2835558.2
A6: North | B6: 330463.11 | C6: 386523.23 | D6: 364567.05 | E6: 545686.09 | F6: 529394.13 | G6: 244894.89 | H6: 2401528.5
A7: South | B7: 388999.42 | C7: 550907.47 | D7: 635816.35 | E7: 434804.53 | F7: 447723.32 | G7: 443729.52 | H7: 2901980.6
A8: West | B8: 449558.42 | C8: 492516.66 | D8: 692708.47 | E8: 485410.84 | F8: 446560.6 | G8: 358578.13 | H8: 2925333.1
A9: (blank) | B9: 2272834.5 | C9: 3395306.3 | D9: 2815443.6 | E9: 2248675.3 | F9: 2307276.9 | G9: 2469011.2 | H9: 15508548
A10: Grand Total | B10: 3671151.5 | C10: 5606379.1 | D10: 4972753.1 | E10: 4325720.4 | F10: 4086952.2 | G10: 3909991.9 | H10: 26572948

Sheet Practice sheet 3
A3: Sum of final_amount | B3: sales_rep_id
A4: Order Month | B4: R001 | C4: R002 | D4: R003 | E4: R004 | F4: R005 | G4: R006 | H4: R007 | I4: R008 | J4: R009 | K4: R010 | L4: R011 | M4: R012 | N4: R013 | O4: R014 | P4: R015 | Q4: R016 | R4: R017 | S4: R018 | T4: R019 | U4: R020 | V4: R021 | W4: R022 | X4: R023 | Y4: R024 | Z4: R025 | AA4: R026 | AB4: R027 | AC4: R028 | AD4: R029 | AE4: R030 | AF4: Grand Total
A5: Apr-24 | B5: 13142.63 | C5: 47732.52 | D5: 95360.5 | E5: 24139.45 | F5: 54151.6 | G5: 48005.38 | H5: 58410.44 | I5: 10200 | J5: 30785.7 | K5: 90702.58 | L5: 16809.8 | N5: 28754.46 | O5: 47799.04 | P5: 38749.1 | Q5: 32076.68 | R5: 10848.42 | S5: 8568.6 | T5: 9214.02 | U5: 59723.72 | V5: 23014.95 | W5: 52618.02 | X5: 77710.48 | Y5: 17676.14 | Z5: 18622.26 | AA5: 20693.66 | AB5: 5372.64 | AC5: 12383.74 | AD5: 42586.65 | AE5: 6927.3 | AF5: 1002780.5
A6: Aug-24 | B6: 24096.66 | C6: 36227.7 | D6: 43450.26 | E6: 19539.78 | F6: 39012.48 | G6: 37982.64 | H6: 87633.61 | I6: 53643.3 | J6: 36122.16 | K6: 33983.58 | L6: 85224.82 | M6: 38382.08 | N6: 31912.1 | O6: 9269.28 | P6: 22723.65 | Q6: 31884.06 | R6: 25035.29 | S6: 76840.68 | U6: 34922.23 | V6: 63472.95 | W6: 48127.75 | X6: 30173.04 | Y6: 31667.7 | Z6: 35478.45 | AA6: 5782.7 | AB6: 30938.52 | AC6: 24732.36 | AD6: 10992.93 | AE6: 2717 | AF6: 1051969.8
A7: Dec-24 | B7: 32469.24 | C7: 34922.44 | D7: 53976.8 | E7: 37588.08 | F7: 20517.04 | G7: 9576.84 | H7: 54216.5 | I7: 55426.24 | J7: 15954 | K7: 81282.36 | M7: 47743.37 | N7: 82363.08 | O7: 29764.32 | P7: 15998.96 | Q7: 45639.42 | R7: 50697.02 | S7: 52352.36 | T7: 833.85 | U7: 53215.12 | V7: 3194.7 | W7: 38341.32 | X7: 62664.12 | Y7: 19205.12 | Z7: 35026.8 | AA7: 12949.3 | AB7: 61362.32 | AC7: 27579.11 | AD7: 43070.58 | AE7: 29721.11 | AF7: 1107651.5
A8: Feb-24 | B8: 23433.82 | C8: 17800.9 | D8: 6311.76 | E8: 39091.5 | F8: 9662.4 | G8: 30935.02 | H8: 13071.78 | I8: 28679.7 | J8: 90904.78 | L8: 21895.66 | O8: 33879.12 | P8: 107702.76 | Q8: 29615.15 | R8: 95717.2 | S8: 34236.2 | T8: 96853.59 | U8: 49449.74 | W8: 66445.63 | X8: 29644.86 | Y8: 42242.76 | Z8: 613.8 | AA8: 2183.8 | AB8: 14480.8 | AC8: 46797.24 | AD8: 38691.8 | AE8: 13251.56 | AF8: 983593.33
A9: Jan-24 | B9: 57888.48 | C9: 10535.7 | E9: 4562.88 | F9: 1944.72 | H9: 3201.66 | I9: 29826.5 | J9: 5938.8 | K9: 62823.26 | L9: 37163.1 | M9: 16317.5 | N9: 35839.02 | O9: 25188.8 | P9: 37259.4 | Q9: 11096.46 | R9: 52756.56 | S9: 35876.04 | T9: 21674.25 | U9: 3544.86 | V9: 8362.64 | W9: 16501.68 | X9: 13056.96 | Y9: 45836.14 | Z9: 29318.65 | AB9: 2550.94 | AC9: 76200.33 | AD9: 36804.42 | AE9: 28551.53 | AF9: 710621.28
A10: Jul-24 | B10: 23504.85 | C10: 40546.62 | D10: 31379.49 | E10: 18431.4 | F10: 11909.7 | G10: 82680.96 | H10: 12961 | J10: 17339.7 | L10: 73419.3 | M10: 54746.51 | N10: 2319.45 | O10: 43642.5 | P10: 52951.08 | Q10: 3344.59 | R10: 96471.29 | S10: 16505.3 | T10: 15307.6 | U10: 11185.16 | V10: 50498.63 | W10: 41669.92 | X10: 13876.59 | Z10: 128732.21 | AA10: 19448.64 | AB10: 12565.02 | AC10: 33246.08 | AD10: 24496.02 | AE10: 58977.67 | AF10: 992157.28
A11: Jun-24 | B11: 32893.8 | C11: 42723.22 | D11: 2167.57 | E11: 33162.84 | F11: 35189.29 | H11: 34212.53 | I11: 52709.58 | J11: 31327.72 | K11: 68943.58 | N11: 38614.56 | O11: 4389.76 | P11: 28971.52 | Q11: 49924.74 | R11: 8854.08 | S11: 35267.1 | T11: 18806.2 | U11: 55295.71 | V11: 22419.54 | W11: 14590.8 | Y11: 40732.96 | Z11: 48729.58 | AA11: 10530.07 | AB11: 14967.44 | AC11: 13144.61 | AD11: 51547.11 | AE11: 42574.6 | AF11: 832690.51
A12: Mar-24 | B12: 53529.58 | C12: 17892.35 | D12: 107614.58 | E12: 17920.36 | F12: 38591.84 | G12: 13982.64 | H12: 30238.34 | I12: 27669.46 | J12: 59850.14 | K12: 17484.81 | L12: 36603.84 | O12: 34768.44 | P12: 87736.56 | Q12: 26366.45 | R12: 701.1 | S12: 59203.19 | U12: 27364.76 | V12: 85035.12 | W12: 45116.6 | X12: 25929.28 | Y12: 74395.45 | Z12: 58234.48 | AA12: 25279.44 | AB12: 12178.5 | AC12: 14509.44 | AD12: 31945.28 | AE12: 4513.08 | AF12: 1034655.1
A13: May-24 | C13: 32944.03 | E13: 14728.1 | F13: 13208.72 | G13: 81523.76 | H13: 49780.61 | I13: 50774.48 | J13: 56878.85 | K13: 67849.4 | M13: 11312.73 | N13: 48333.21 | O13: 12376.88 | P13: 33794.46 | Q13: 55387.32 | R13: 4176.52 | S13: 20749.26 | T13: 20488.14 | V13: 26189.4 | W13: 84834.12 | X13: 28208.1 | Y13: 2697 | Z13: 1321.17 | AA13: 219.3 | AB13: 23817.95 | AC13: 22052.4 | AD13: 74682.04 | AE13: 10903.76 | AF13: 849231.71
A14: Nov-24 | B14: 49896.08 | C14: 27434.95 | D14: 45417.86 | E14: 19041.68 | F14: 11080.41 | G14: 50573.81 | I14: 41452.51 | J14: 26772.04 | K14: 19890.5 | L14: 18845.05 | M14: 22938.72 | N14: 11875.5 | O14: 13261.8 | P14: 62540.36 | Q14: 4969.2 | R14: 40020.01 | S14: 25461 | T14: 36824.04 | U14: 49494.72 | V14: 7484.4 | W14: 64550.16 | X14: 15733.12 | Y14: 37299.08 | Z14: 13399.6 | AA14: 48488.96 | AB14: 27900.65 | AC14: 7854.86 | AD14: 29735.56 | AE14: 58880.84 | AF14: 889117.47
A15: Oct-24 | B15: 52418.58 | C15: 2627 | D15: 43580.08 | E15: 5319.9 | G15: 992.83 | H15: 20387.16 | I15: 7867.23 | K15: 95879.36 | L15: 10273.83 | M15: 51497.4 | N15: 44750.97 | O15: 2983.04 | R15: 1905.6 | S15: 14152 | T15: 48165.08 | U15: 11091.6 | V15: 23029.48 | X15: 5393.04 | Y15: 51855.65 | Z15: 46532.98 | AA15: 29401.74 | AB15: 82393.02 | AC15: 83207.24 | AD15: 23482.44 | AE15: 59509.19 | AF15: 818696.44
A16: Sep-24 | B16: 10086.18 | C16: 25577.5 | D16: 3736.42 | E16: 7928.34 | F16: 45555.24 | G16: 2927.4 | H16: 73512.2 | I16: 81426.6 | J16: 15341.5 | K16: 19266.78 | L16: 15044.16 | M16: 31566.82 | N16: 297.9 | O16: 7592.03 | P16: 63801.75 | Q16: 42145.2 | S16: 58108.22 | T16: 7421.26 | U16: 43602.46 | V16: 38732.55 | W16: 31340.4 | X16: 45172.89 | Y16: 13815.1 | Z16: 1556.1 | AA16: 13260 | AB16: 37300.28 | AC16: 20481.06 | AD16: 5856 | AE16: 28783.2 | AF16: 791235.54
A17: (blank) | B17: 416489.7 | C17: 643098.73 | D17: 553697.59 | E17: 347571.98 | F17: 501621.89 | G17: 779467.45 | H17: 418123.85 | I17: 421877.73 | J17: 527339.33 | K17: 322238.99 | L17: 419928.2 | M17: 626889.19 | N17: 486464.13 | O17: 730798.53 | P17: 539510.58 | Q17: 482114.44 | R17: 393201.32 | S17: 674969.69 | T17: 695595.49 | U17: 507217.63 | V17: 410072.81 | W17: 565434.14 | X17: 636225 | Y17: 442135.48 | Z17: 483732.81 | AA17: 388067.47 | AB17: 591264.54 | AC17: 498279.58 | AD17: 602805.97 | AE17: 402313.53 | AF17: 15508548
A18: Grand Total | B18: 789849.6 | C18: 980063.66 | D18: 986692.91 | E18: 589026.29 | F18: 782445.33 | G18: 1138648.7 | H18: 855749.68 | I18: 861553.33 | J18: 914554.72 | K18: 880345.2 | L18: 735207.76 | M18: 901394.32 | N18: 811524.38 | O18: 995713.54 | P18: 1091740.2 | Q18: 814563.71 | R18: 780384.41 | S18: 1112289.6 | T18: 971183.52 | U18: 906107.71 | V18: 761507.17 | W18: 1069570.5 | X18: 983787.48 | Y18: 819558.58 | Z18: 901298.89 | AA18: 576305.08 | AB18: 917092.62 | AC18: 880468.05 | AD18: 1016696.8 | AE18: 747624.37 | AF18: 26572948
B20: =MAX(GETPIVOTDATA("final_amount",$A$3,"Order Month",)) -> 15508548

Sheet Practice sheet 4
A3: Sum of final_amount | B3: category
A4: Sales Region | B4: Apparel | C4: Beauty | D4: Electronics | E4: Grocery | F4: Home | G4: Sports | H4: Grand Total
A5: East | B5: 0.080864547 | C5: 0.27547499 | D5: 0.16371296 | E5: 0.2155285 | F5: 0.12554751 | G5: 0.1388715 | H5: 1
A6: North | B6: 0.13760533 | C6: 0.16094884 | D6: 0.15180626 | E6: 0.22722449 | F6: 0.22044049 | G6: 0.10197459 | H6: 1
A7: South | B7: 0.13404618 | C7: 0.18983844 | D7: 0.21909738 | E7: 0.14983027 | F7: 0.15428198 | G7: 0.15290575 | H7: 1
A8: West | B8: 0.15367768 | C8: 0.16836259 | D8: 0.23679644 | E8: 0.16593353 | F8: 0.15265291 | G8: 0.12257685 | H8: 1
A9: (blank) | B9: 0.14655366 | C9: 0.21893129 | D9: 0.18154141 | E9: 0.14499587 | F9: 0.14877453 | G9: 0.15920325 | H9: 1
A10: Grand Total | B10: 0.13815372 | C10: 0.21098069 | D10: 0.18713592 | E10: 0.16278662 | F10: 0.15380123 | G10: 0.14714182 | H10: 1

Sheet Practice sheet 5
A1: order_date | B1: SUM of final_amount
A2: Qtr1 | B2: 6679619.9
A3: Qtr2 | B3: 6828784.2
A4: Qtr3 | B4: 6555757.3
A5: Qtr4 | B5: 6452211.9
A6: Grand Total | B6: 26516373

Sheet Practice sheet 6
A2: order_date | B2: SUM of final_amount | C2: Average of profit_margin
A3: Qtr1 | B3: 6679619.9 | C3: 0.46195941
A4: Qtr2 | B4: 6828784.2 | C4: 0.451484
A5: Qtr3 | B5: 6555757.3 | C5: 0.45403629
A6: Qtr4 | B6: 6452211.9 | C6: 0.45636311
A7: Grand Total | B7: 26516373 | C7: 0.45599884

Sheet Practice sheet 7
A3: Row Labels | B3: Sum of final_amount
A4: R001 | B4: 789849.6
A5: R002 | B5: 980063.66
A6: R003 | B6: 986692.91
A7: R004 | B7: 589026.29
A8: R005 | B8: 782445.33
A9: R006 | B9: 1138648.7
A10: R007 | B10: 855749.68
A11: R008 | B11: 861553.33
A12: R009 | B12: 914554.72
A13: R010 | B13: 880345.2
A14: R011 | B14: 735207.76
A15: R012 | B15: 901394.32
... A34: Grand Total | B34: 26572948

Sheet Q5_Advanced
A1: Q5 - ADVANCED (10 marks total)
A2: RANK · Running Totals · TEXTJOIN · LARGE + INDEX/MATCH · Multi-condition top-N
A4: Q# | B4: Question | C4: Marks | D4: Hint | E4: Your Answer | F4: Format
A5: Q5.1 | B5: Rank all sales reps by total revenue (highest = rank 1). Who (name) is at RANK #7? | C5: 2 | D5: Per-rep totals, then use RANK.EQ, or sort. Return the rep_name at position 7. | E5: {=INDEX(Sales_Reps!$B$2:$B$31, MATCH(LARGE(SUMIFS(Orders!$I$2:$I$2001, Orders!$E$2:$E$2001, Sales_Reps!$A$2:$A$31), 7), SUMIFS(Orders!$I$2:$I$2001, Orders!$E$2:$E$2001, Sales_Reps!$A$2:$A$31), 0))} -> Amit Singh | F5: Text
A6: Q5.2 | B6: What is the CUMULATIVE revenue from Jan 2024 through the end of Aug 2024? (Sum of final_amount where order_date <= 31-Aug-2024.) | C6: 2 | D6: SUMIFS with date <=. | E6: =SUMIFS(Orders!$I$2:$I$2001, Orders!$B$2:$B$2001, "<=2024-08-31") -> 18050690 | F6: Currency
A7: Q5.3 | B7: Among orders where the sales rep is in the WEST region: which product (by name) has the 2nd highest total revenue? | C7: 3 | D7: Helper: sales_region on orders. Filter/pivot to West, sum by product, rank, get #2, VLOOKUP product name. | E7: {=INDEX(Products!$B$2:$B$51, MATCH(LARGE(SUMIFS(Orders!$I$2:$I$2001, Orders!$D$2:$D$2001, Products!$A$2:$A$51, Orders!$E$2:$E$2001, _xlfn._xlws.FILTER(Sales_Reps!$A$2:$A$31, Sales_Reps!$C$2:$C$31="West")), 2), SUMIFS(Orders!$I$2:$I$2001, Orders!$D$2:$D$2001, Products!$A$2:$A$51, Orders!$E$2:$E$2001, _xlfn._xlws.FILTER(Sales_Reps!$A$2:$A$31, Sales_Reps!$C$2:$C$31="West")), 0))} -> Laptop Bag | F7: Text
A8: Q5.4 | B8: Concatenate the names of the top 5 reps by revenue into a single cell, separated by " | " (space-pipe-space). | C8: 2 | D8: TEXTJOIN with delimiter " | ". Combine with LARGE to pull top 5. | E8: {=_xlfn.TEXTJOIN(" | ", TRUE, _xlfn.TAKE(_xlfn.SORTBY(Sales_Reps!$B$2:$B$31, SUMIFS(Orders!$I$2:$I$2001, Orders!$E$2:$E$2001, Sales_Reps!$A$2:$A$31), -1), 5))} -> Neha Desai | Shalini Patel | Deepak Shah | Nisha Menon | Arun Iyer | F8: Text
A9: Q5.5 | B9: What is the HIGHEST single order value (final_amount) where ship_city = "Bengaluru" AND the product's category = "Grocery"? | C9: 1 | D9: MAXIFS with a category helper column, or nested MAX(IF()). | E9: =_xlfn.MAXIFS(Orders!$I$2:$I$2001, Orders!$K$2:$K$2001, "Bengaluru", Orders!$L$2:$L$2001, "Grocery") -> 22134 | F9: Currency
E10: 6

Sheet Sheet1
